<?xml version="1.0" encoding="utf-8"?>
<!-- This URDF was automatically created by SolidWorks to URDF Exporter! Originally created by Stephen Brawner (brawner@gmail.com) 
     Commit Version: 1.6.0-1-g15f4949  Build Version: 1.6.7594.29634
     For more information, please see http://wiki.ros.org/sw_urdf_exporter -->
<robot
  name="robot_differential_sena">
  <link
    name="base_link">
    <inertial>
      <origin
        xyz="0 0 0"
        rpy="0 0 0" />
      <mass
        value="3" />
      <inertia
        ixx="0.0033159"
        ixy="-3.0788E-08"
        ixz="-1.2284E-07"
        iyy="0.004271"
        iyz="-0.00014007"
        izz="0.0068628" />
    </inertial>
    <visual>
      <origin
        xyz="0 0 0"
        rpy="0 0 0" />
      <geometry>
        <mesh
          filename="package://robot_differential_sena/meshes/base_link.STL" />
      </geometry>
      <material
        name="">
        <color
          rgba="0.79216 0.81961 0.93333 1" />
      </material>
    </visual>
    <collision>
      <origin
        xyz="0 0 0"
        rpy="0 0 0" />
      <geometry>
        <mesh
          filename="package://robot_differential_sena/meshes/base_link.STL" />
      </geometry>
    </collision>
  </link>
  <link
    name="RuedaIzquierda_link">
    <inertial>
      <origin
        xyz="0 0 0"
        rpy="0 0 0" />
      <mass
        value="0.033874" />
      <inertia
        ixx="2.3297E-05"
        ixy="2.9866E-12"
        ixz="-6.1004E-12"
        iyy="1.2633E-05"
        iyz="5.6052E-10"
        izz="1.2633E-05" />
    </inertial>
    <visual>
      <origin
        xyz="0 0 0"
        rpy="0 0 0" />
      <geometry>
        <mesh
          filename="package://robot_differential_sena/meshes/RuedaIzquierda_link.STL" />
      </geometry>
      <material
        name="">
        <color
          rgba="0.75294 0.75294 0.75294 1" />
      </material>
    </visual>
    <collision>
      <origin
        xyz="0 0 0"
        rpy="0 0 0" />
      <geometry>
        <mesh
          filename="package://robot_differential_sena/meshes/RuedaIzquierda_link.STL" />
      </geometry>
    </collision>
  </link>
  <joint
    name="RuedaIzquierda_joint"
    type="continuous">
    <origin
      xyz="-0.08245 0.056047 0.0195"
      rpy="2.6278 0 0" />
    <parent
      link="base_link" />
    <child
      link="RuedaIzquierda_link" />
    <axis
      xyz="-1 0 0" />
  </joint>
  <link
    name="RuedaDerecha_link">
    <inertial>
      <origin
        xyz="0 0 0"
        rpy="0 0 0" />
      <mass
        value="0.033874" />
      <inertia
        ixx="2.3297E-05"
        ixy="2.9866E-12"
        ixz="-6.1004E-12"
        iyy="1.2633E-05"
        iyz="5.6052E-10"
        izz="1.2633E-05" />
    </inertial>
    <visual>
      <origin
        xyz="0 0 0"
        rpy="0 0 0" />
      <geometry>
        <mesh
          filename="package://robot_differential_sena/meshes/RuedaDerecha_link.STL" />
      </geometry>
      <material
        name="">
        <color
          rgba="0.75294 0.75294 0.75294 1" />
      </material>
    </visual>
    <collision>
      <origin
        xyz="0 0 0"
        rpy="0 0 0" />
      <geometry>
        <mesh
          filename="package://robot_differential_sena/meshes/RuedaDerecha_link.STL" />
      </geometry>
    </collision>
  </link>
  <joint
    name="RuedaDerecha_joint"
    type="continuous">
    <origin
      xyz="0.08245 0.056047 0.0195"
      rpy="-1.8147 0 3.1416" />
    <parent
      link="base_link" />
    <child
      link="RuedaDerecha_link" />
    <axis
      xyz="1 0 0" />
  </joint>
  <link
    name="Camara_link">
    <inertial>
      <origin
        xyz="-5.878E-05 0.0011119 -0.0003685"
        rpy="0 0 0" />
      <mass
        value="0" />
      <inertia
        ixx="1.7534E-06"
        ixy="-7.2563E-11"
        ixz="1.0539E-09"
        iyy="1.574E-05"
        iyz="-2.3537E-08"
        izz="1.6733E-05" />
    </inertial>
    <visual>
      <origin
        xyz="0 0 0"
        rpy="0 0 0" />
      <geometry>
        <mesh
          filename="package://robot_differential_sena/meshes/Camara_link.STL" />
      </geometry>
      <material
        name="">
        <color
          rgba="0.75294 0.75294 0.75294 1" />
      </material>
    </visual>
    <collision>
      <origin
        xyz="0 0 0"
        rpy="0 0 0" />
      <geometry>
        <mesh
          filename="package://robot_differential_sena/meshes/Camara_link.STL" />
      </geometry>
    </collision>
  </link>
  <joint
    name="Camara_joint"
    type="fixed">
    <origin
      xyz="-0.0019769 0.09428 0.1277"
      rpy="-1.5708 0 0.01852" />
    <parent
      link="base_link" />
    <child
      link="Camara_link" />
    <axis
      xyz="0 0 0" />
  </joint>
  <link
    name="Lidar_link">
    <inertial>
      <origin
        xyz="-0.0074842 -0.010758 -9.2198E-05"
        rpy="0 0 0" />
      <mass
        value="0" />
      <inertia
        ixx="0.00060896"
        ixy="-0.00015822"
        ixz="-8.019E-07"
        iyy="0.001091"
        iyz="3.1026E-06"
        izz="0.00095226" />
    </inertial>
    <visual>
      <origin
        xyz="0 0 0"
        rpy="0 0 0" />
      <geometry>
        <mesh
          filename="package://robot_differential_sena/meshes/Lidar_link.STL" />
      </geometry>
      <material
        name="">
        <color
          rgba="1 0.96471 0.84314 1" />
      </material>
    </visual>
    <collision>
      <origin
        xyz="0 0 0"
        rpy="0 0 0" />
      <geometry>
        <mesh
          filename="package://robot_differential_sena/meshes/Lidar_link.STL" />
      </geometry>
    </collision>
  </link>
  <joint
    name="Lidar_joint"
    type="fixed">
    <origin
      xyz="0 0.07275 0.2396"
      rpy="-1.5708 0 -1.5708" />
    <parent
      link="base_link" />
    <child
      link="Lidar_link" />
    <axis
      xyz="0 0 0" />
  </joint>


    <!--              GAZEBO PLUGINS                     -->


  <!--                    differential_drive_controller               -->
  <gazebo>
    <plugin filename="libgazebo_ros_diff_drive.so" name="differential_drive_controller">
      <leftJoint>RuedaIzquierda_joint</leftJoint>
      <legacyMode>false</legacyMode>
      <rightJoint>RuedaDerecha_joint</rightJoint>

      <robotBaseFrame>base_link</robotBaseFrame>
      <wheelSeperation>0.235</wheelSeperation>
      <wheelDiameter>0.068</wheelDiameter>
      <publishWheelJointState>true</publishWheelJointState>
    </plugin>
  </gazebo>


 <!-- camera -->
  <gazebo reference="Camara_link">
    <sensor type="camera" name="camera1">
      <update_rate>30.0</update_rate>
      <camera name="head">
        <pose>-0.2 0 0 -1.5708 -1.5708 0</pose>
        <horizontal_fov>1.3962634</horizontal_fov>
        <image>
          <width>800</width>
          <height>800</height>
          <format>R8G8B8</format>
        </image>
        <clip>
          <near>0.02</near>
          <far>300</far>
        </clip>
        <noise>
          <type>gaussian</type>
          <!-- Noise is sampled independently per pixel on each frame.
               That pixel's noise value is added to each of its color
               channels, which at that point lie in the range [0,1]. -->
          <mean>0.0</mean>
          <stddev>0.007</stddev>
        </noise>
      </camera>
      <plugin name="camera_controller" filename="libgazebo_ros_camera.so">
        <alwaysOn>true</alwaysOn>
        <updateRate>0.0</updateRate>
        <cameraName>robot_differential_sena/camera1</cameraName>
        <imageTopicName>image_raw</imageTopicName>
        <cameraInfoTopicName>camera_info</cameraInfoTopicName>
        <frameName>Camara_link</frameName>
        <hackBaseline>0.07</hackBaseline>
        <distortionK1>0.0</distortionK1>
        <distortionK2>0.0</distortionK2>
        <distortionK3>0.0</distortionK3>
        <distortionT1>0.0</distortionT1>
        <distortionT2>0.0</distortionT2>
      </plugin>
    </sensor>
  </gazebo>




</robot>