<?xml version="1.0" encoding="utf-8"?>
<!-- This URDF was automatically created by SolidWorks to URDF Exporter! Originally created by Stephen Brawner (brawner@gmail.com) 
     Commit Version: 1.6.0-1-g15f4949  Build Version: 1.6.7594.29634
     For more information, please see http://wiki.ros.org/sw_urdf_exporter -->
<robot
  name="robot_differential_sena">
  <link
    name="base_link">
    <inertial>
      <origin
        xyz="-0.00071212 -0.046397 0.099495"
        rpy="0 0 0" />
      <mass
        value="3" />
      <inertia
        ixx="0.003316"
        ixy="0"
        ixz="0"
        iyy="0.0042711"
        iyz="0"
        izz="0.0068629" />
    </inertial>
    <visual>
      <origin
        xyz="0 0 0"
        rpy="0 0 0" />
      <geometry>
        <mesh
          filename="package://robot_differential_sena/meshes/base_link.STL" />
      </geometry>
      <material
        name="">
        <color
          rgba="0.61961 0.40784 0.2 1" />
      </material>
    </visual>
    <collision>
      <origin
        xyz="0 0 0"
        rpy="0 0 0" />
      <geometry>
        <mesh
          filename="package://robot_differential_sena/meshes/base_link.STL" />
      </geometry>
    </collision>
  </link>
  <link
    name="RuedaIzquierda_Link">
    <inertial>
      <origin
        xyz="-0.018807 1.1948E-08 -5.6798E-08"
        rpy="0 0 0" />
      <mass
        value="0.033874" />
      <inertia
        ixx="2.3297E-05"
        ixy="2.9866E-12"
        ixz="-6.1004E-12"
        iyy="1.2633E-05"
        iyz="5.6052E-10"
        izz="1.2633E-05" />
    </inertial>
    <visual>
      <origin
        xyz="0 0 0"
        rpy="0 0 0" />
      <geometry>
        <mesh
          filename="package://robot_differential_sena/meshes/RuedaIzquierda_Link.STL" />
      </geometry>
      <material
        name="">
        <color
          rgba="0.75294 0.75294 0.75294 1" />
      </material>
    </visual>
    <collision>
      <origin
        xyz="0 0 0"
        rpy="0 0 0" />
      <geometry>
        <mesh
          filename="package://robot_differential_sena/meshes/RuedaIzquierda_Link.STL" />
      </geometry>
    </collision>
  </link>
  <joint
    name="RuedaIzquierda_Joint"
    type="continuous">
    <origin
      xyz="-0.0824500000000007 0.0560468635614915 0.0195000000000003"
      rpy="2.18695048006706 0 0" />
    <parent
      link="base_link" />
    <child
      link="RuedaIzquierda_Link" />
    <axis
      xyz="1 0 0" />
  </joint>
  <link
    name="RuedaDerecha_Link">
    <inertial>
      <origin
        xyz="-0.018807 1.1948E-08 -5.6798E-08"
        rpy="0 0 0" />
      <mass
        value="0.033874" />
      <inertia
        ixx="2.3297E-05"
        ixy="2.9866E-12"
        ixz="-6.1004E-12"
        iyy="1.2633E-05"
        iyz="5.6052E-10"
        izz="1.2633E-05" />
    </inertial>
    <visual>
      <origin
        xyz="0 0 0"
        rpy="0 0 0" />
      <geometry>
        <mesh
          filename="package://robot_differential_sena/meshes/RuedaDerecha_Link.STL" />
      </geometry>
      <material
        name="">
        <color
          rgba="0.75294 0.75294 0.75294 1" />
      </material>
    </visual>
    <collision>
      <origin
        xyz="0 0 0"
        rpy="0 0 0" />
      <geometry>
        <mesh
          filename="package://robot_differential_sena/meshes/RuedaDerecha_Link.STL" />
      </geometry>
    </collision>
  </link>
  <joint
    name="RuedaDerecha_Joint"
    type="continuous">
    <origin
      xyz="0.0824499999999997 0.0560468635614933 0.0194999999999997"
      rpy="-2.4864570903593 0 3.14159265358979" />
    <parent
      link="base_link" />
    <child
      link="RuedaDerecha_Link" />
    <axis
      xyz="1 0 0" />
  </joint>
  <link
    name="Camara_Link">
    <inertial>
      <origin
        xyz="-5.878E-05 0.0011119 -0.0003685"
        rpy="0 0 0" />
      <mass
        value="0.01531" />
      <inertia
        ixx="1.7534E-06"
        ixy="-7.2563E-11"
        ixz="1.0539E-09"
        iyy="1.574E-05"
        iyz="-2.3537E-08"
        izz="1.6733E-05" />
    </inertial>
    <visual>
      <origin
        xyz="0 0 0"
        rpy="0 0 0" />
      <geometry>
        <mesh
          filename="package://robot_differential_sena/meshes/Camara_Link.STL" />
      </geometry>
      <material
        name="">
        <color
          rgba="0.75294 0.75294 0.75294 1" />
      </material>
    </visual>
    <collision>
      <origin
        xyz="0 0 0"
        rpy="0 0 0" />
      <geometry>
        <mesh
          filename="package://robot_differential_sena/meshes/Camara_Link.STL" />
      </geometry>
    </collision>
  </link>
  <joint
    name="Camara_Joint"
    type="fixed">
    <origin
      xyz="-0.00195837494962821 0.0932796943801035 0.1263"
      rpy="1.5707963267949 0 0.0185195771248791" />
    <parent
      link="base_link" />
    <child
      link="Camara_Link" />
    <axis
      xyz="0 0 0" />
  </joint>
  <link
    name="Lidar_Link">
    <inertial>
      <origin
        xyz="-0.0074842 -0.010758 -9.2198E-05"
        rpy="0 0 0" />
      <mass
        value="0" />
      <inertia
        ixx="0.00060896"
        ixy="-0.00015822"
        ixz="-8.019E-07"
        iyy="0.001091"
        iyz="3.1026E-06"
        izz="0.00095226" />
    </inertial>
    <visual>
      <origin
        xyz="0 0 0"
        rpy="0 0 0" />
      <geometry>
        <mesh
          filename="package://robot_differential_sena/meshes/Lidar_Link.STL" />
      </geometry>
      <material
        name="">
        <color
          rgba="1 0.96471 0.84314 1" />
      </material>
    </visual>
    <collision>
      <origin
        xyz="0 0 0"
        rpy="0 0 0" />
      <geometry>
        <mesh
          filename="package://robot_differential_sena/meshes/Lidar_Link.STL" />
      </geometry>
    </collision>
  </link>
  <joint
    name="Lidar_Joint"
    type="fixed">
    <origin
      xyz="0 0.07275 0.2396"
      rpy="-1.5707963267949 0 -1.5707963267949" />
    <parent
      link="base_link" />
    <child
      link="Lidar_Link" />
    <axis
      xyz="0 0 0" />
  </joint>
</robot>